<?xml version="1.0" ?>
<robot xmlns:xacro="http://ros.org/wiki/xacro">
  
  <xacro:macro name="joint_transmission_macro" params="joint_name">
    <transmission name="${joint_name}_transmssion">
      <type>transmission_interface/SimpleTransmission</type>
      <joint name="${joint_name}">
        <hardwareInterface>hardware_interface/PositionJointInterface</hardwareInterface>
      </joint>  
      <actuator name="${joint_name}_motor">
        <mechanicalReduction>1</mechanicalReduction>
      </actuator>
    </transmission>
  </xacro:macro>

  <xacro:macro name="fanuc_cr7ial" params="prefix">
    <!-- links: main serial chain -->
    <link name="${prefix}base_link">
      <visual>
        <origin xyz="0 0 0" rpy="0 0 0"/>
        <geometry>
          <mesh filename="package://fl_description/meshes/cr7ia/visual/base_link.stl"/>
        </geometry>   
      </visual>
      <collision>
        <origin xyz="0 0 0" rpy="0 0 0"/>
        <geometry>
          <mesh filename="package://fl_description/meshes/cr7ia/collision/base_link.stl"/>
        </geometry>
      </collision>
      <inertial>
        <mass value="100"/>
        <inertia 
          ixx="0" ixy="0" ixz="0" 
          iyy="0" iyz="0" 
          izz="0"/>
      </inertial>
    </link>
    <link name="${prefix}link_1">
      <visual>
        <origin xyz="0 0 0" rpy="0 0 0"/>
        <geometry>
          <mesh filename="package://fl_description/meshes/cr7ia/visual/link_1.stl"/>
        </geometry>
      </visual>
      <collision>
        <origin xyz="0 0 0" rpy="0 0 0"/>
        <geometry>
          <mesh filename="package://fl_description/meshes/cr7ia/collision/link_1.stl"/>
        </geometry>
      </collision>
      <inertial>
        <mass value="15"/>
        <inertia 
          ixx="0" ixy="0" ixz="0" 
          iyy="0" iyz="0" 
          izz="0"/>
      </inertial>
    </link>
    <link name="${prefix}link_2">
      <visual>
        <origin xyz="0 0 0" rpy="0 0 0"/>
        <geometry>
          <mesh filename="package://fl_description/meshes/cr7ial/visual/link_2.stl"/>
        </geometry>
      </visual>
      <collision>
        <origin xyz="0 0 0" rpy="0 0 0"/>
        <geometry>
          <mesh filename="package://fl_description/meshes/cr7ial/collision/link_2.stl"/>
        </geometry>
      </collision>
      <inertial>
        <mass value="7"/>
        <inertia 
          ixx="0" ixy="0" ixz="0" 
          iyy="0" iyz="0"
          izz="0"/>
      </inertial>
    </link>
    <link name="${prefix}link_3">
      <visual>
        <origin xyz="0 0 0" rpy="0 0 0"/>
        <geometry>
          <mesh filename="package://fl_description/meshes/cr7ia/visual/link_3.stl"/>
        </geometry>
      </visual>
      <collision>
        <origin xyz="0 0 0" rpy="0 0 0"/>
        <geometry>
          <mesh filename="package://fl_description/meshes/cr7ia/collision/link_3.stl"/>
        </geometry>
      </collision>
      <inertial>
        <mass value="4"/>
        <inertia 
          ixx="0" ixy="0" ixz="0" 
          iyy="0" iyz="0" 
          izz="0"/>
      </inertial>
    </link>
    <link name="${prefix}link_4">
      <visual>
        <origin xyz="0 0 0" rpy="0 0 0"/>
        <geometry>
          <mesh filename="package://fl_description/meshes/cr7ial/visual/link_4.stl"/>
        </geometry>
      </visual>
      <collision>
        <origin xyz="0 0 0" rpy="0 0 0"/>
        <geometry>
          <mesh filename="package://fl_description/meshes/cr7ial/collision/link_4.stl"/>
        </geometry>
      </collision>
      <inertial>
        <mass value="4"/>
        <inertia 
          ixx="0.47" ixy="0" ixz="0" 
          iyy="0" iyz="0" 
          izz="0"/>
      </inertial>
    </link>
    <link name="${prefix}link_5">
      <visual>
        <origin xyz="0 0 0" rpy="0 0 0"/>
        <geometry>
          <mesh filename="package://fl_description/meshes/cr7ia/visual/link_5.stl"/>
        </geometry>
      </visual>
      <collision>
        <origin xyz="0 0 0" rpy="0 0 0"/>
        <geometry>
          <mesh filename="package://fl_description/meshes/cr7ia/collision/link_5.stl"/>
        </geometry>
      </collision>
      <inertial>
        <mass value="1"/>
        <inertia 
          ixx="0" ixy="0" ixz="0" 
          iyy="0.47" iyz="0" 
          izz="0"/>
      </inertial>
    </link>
    <link name="${prefix}link_6">
      <visual>
        <origin xyz="0 0 0" rpy="0 0 0"/>
        <geometry>
          <mesh filename="package://fl_description/meshes/cr7ia/visual/link_6.stl"/>
        </geometry>
      </visual>
      <collision>
        <origin xyz="0 0 0" rpy="0 0 0"/>
        <geometry>
          <mesh filename="package://fl_description/meshes/cr7ia/collision/link_6.stl"/>
        </geometry>
      </collision>
      <inertial>
        <mass value="1"/>
        <inertia 
          ixx="0.15" ixy="0" ixz="0" 
          iyy="0" iyz="0" 
          izz="0"/>
      </inertial>
    </link>

    <!-- joints: main serial chain -->   
    <joint name="${prefix}joint_1" type="revolute">
      <origin xyz="0 0 0.457" rpy="0 0 0" />
      <parent link="${prefix}base_link" />
      <child link="${prefix}link_1" />
      <axis xyz="0 0 1" />
      <limit effort="0" lower="-2.9671" upper="2.9671" velocity="6.4577" />
    </joint>
    <joint name="${prefix}joint_2" type="revolute">
      <origin xyz="0.05 0 0" rpy="0 0 0" />
      <parent link="${prefix}link_1" />
      <child link="${prefix}link_2" />
      <axis xyz="0 1 0" />
      <limit effort="0" lower="-1.15192" upper="1.74533" velocity="5.4105" />
    </joint>
    <joint name="${prefix}joint_3" type="revolute">
      <origin xyz="0 0 0.440" rpy="0 0 0" />
      <parent link="${prefix}link_2" />
      <child link="${prefix}link_3" />
      <axis xyz="0 -1 0" />
      <limit effort="0" lower="-0.802851" upper="3.10669" velocity="7.1558" />
    </joint>
    <joint name="${prefix}joint_4" type="revolute">
      <origin xyz="0 0 0.035" rpy="0 0 0"/>
      <parent link="${prefix}link_3"/>
      <child link="${prefix}link_4"/>
      <axis xyz="-1 0 0"/>
      <limit effort="0" lower="-3.3161" upper="3.3161" velocity="9.5993" />
    </joint>
    <joint name="${prefix}joint_5" type="revolute">
      <origin xyz="0.420 0 0" rpy="0 0 0"/>
      <parent link="${prefix}link_4"/>
      <child link="${prefix}link_5"/>
      <axis xyz="0 -1 0"/>
      <limit effort="0" lower="-2.0944" upper="2.0944" velocity="9.5120" />
    </joint>
    <joint name="${prefix}joint_6" type="revolute">
      <origin xyz="0.080 0 0" rpy="0 0 0"/>
      <parent link="${prefix}link_5"/>
      <child link="${prefix}link_6"/>
      <axis xyz="-1 0 0"/>
      <limit effort="0" lower="-6.2832" upper="6.2832" velocity="17.4532" />
    </joint>

    <!-- ROS-Industrial 'base' frame: base_link to Fanuc World Coordinates transform -->
    <link name="${prefix}base" />
    <joint name="${prefix}base_link-base" type="fixed">
      <origin xyz="0 0 0.457" rpy="0 0 0"/>
      <parent link="${prefix}base_link"/>
      <child link="${prefix}base"/>
    </joint>

    <!-- ROS-Industrial 'flange' frame: attachment point for EEF models -->
    <link name="${prefix}flange" />
    <joint name="${prefix}joint_6-flange" type="fixed">
      <origin xyz="0 0 0" rpy="0 0 0" />
      <parent link="${prefix}link_6" />
      <child link="${prefix}flange" />
    </joint>

    <!-- ROS-Industrial 'tool0' frame: all-zeros tool frame -->
    <link name="${prefix}tool0" />
    <joint name="${prefix}link_6-tool0" type="fixed">
      <origin xyz="0 0 0" rpy="${pi} ${-pi/2.0} 0" />
      <parent link="${prefix}link_6" />
      <child link="${prefix}tool0" />
    </joint>



  <joint_transmission_macro joint_name="${prefix}joint_1"/>
  <joint_transmission_macro joint_name="${prefix}joint_2"/>
  <joint_transmission_macro joint_name="${prefix}joint_3"/>
  <joint_transmission_macro joint_name="${prefix}joint_4"/>
  <joint_transmission_macro joint_name="${prefix}joint_5"/>
  <joint_transmission_macro joint_name="${prefix}joint_6"/>

    <gazebo reference="base_link">
    <material>Gazebo/Green</material>
    </gazebo>
    <gazebo reference="link_1">
    <material>Gazebo/Gray</material>
    </gazebo>
    <gazebo reference="link_2">
    <material>Gazebo/Green</material>
    </gazebo>
    <gazebo reference="link_3">
    <material>Gazebo/Gray</material>
    </gazebo>
    <gazebo reference="link_4">
    <material>Gazebo/Green</material>
    </gazebo>
    <gazebo reference="link_5">
    <material>Gazebo/Gray</material>
    </gazebo>
    <gazebo reference="link_6">
    <material>Gazebo/Black</material>
    </gazebo>

  </xacro:macro>
</robot>
